Workbook

Sheet Comparison
A1: Portfolio Comparison — 5 Names Ranked by Margin of Safety
A2: Each model uses Buffett-style conservative assumptions (15-yr horizon, ~9% discount, mid-single-digit growth)
A4: RANK | B4: Ticker | C4: Currency | D4: Current Price | E4: Intrinsic Value | F4: Upside % | G4: Verdict | H4: Key Risk
A5: 1 | B5: UNH | C5: USD | D5: ='Portfolio DCF'!C85 | E5: ='Portfolio DCF'!C84 | F5: ='Portfolio DCF'!C86 | G5: BUY | H5: Medicare Advantage margin pressure, regulatory scrutiny
A6: 2 | B6: LEN | C6: USD | D6: ='Portfolio DCF'!E85 | E6: ='Portfolio DCF'!E84 | F6: ='Portfolio DCF'!E86 | G6: BUY | H6: Housing cycle bottom — FY25 FCF collapsed; recovery dependent on rates
A7: 3 | B7: 1810.HK | C7: HKD | D7: ='Portfolio DCF'!D85 | E7: ='Portfolio DCF'!D84 | F7: ='Portfolio DCF'!D86 | G7: FAIR | H7: China geopolitical risk, EV competition, no buybacks
A8: 4 | B8: TTE | C8: USD | D8: ='Portfolio DCF'!G85 | E8: ='Portfolio DCF'!G84 | F8: ='Portfolio DCF'!G86 | G8: FAIR | H8: Oil price cyclicality; energy transition long-term
A9: 5 | B9: POOL | C9: USD | D9: ='Portfolio DCF'!F85 | E9: ='Portfolio DCF'!F84 | F9: ='Portfolio DCF'!F86 | G9: FAIR | H9: Pool industry slowdown; consumer discretionary
A10: 6 | B10: DPZ | C10: USD | D10: ='Portfolio DCF'!B85 | E10: ='Portfolio DCF'!B84 | F10: ='Portfolio DCF'!B86 | G10: HOLD | H10: Fair value at $372; needs better entry — Buffett bought at $437 = ~fair
A11: 7 | B11: NVDA | C11: USD | D11: ='Portfolio DCF'!H85 | E11: ='Portfolio DCF'!H84 | F11: ='Portfolio DCF'!H86 | G11: AVOID | H11: Priced for perfection at $5T market cap; 18% growth assumed but discount rate haircut
A12: KEY INSIGHTS BY NAME
A13: UNH (+76% upside) — BIGGEST OPPORTUNITY
A14: • Trading at $354 vs intrinsic $621. Stock crushed in 2025-26 from MA pressure + DOJ probes.
A15: • LTM FCF $17.4B is depressed; normalized FCF capacity ~$24B+ with margin recovery
A16: • Mgmt RAISED FY26 guide to $18.25 adj EPS in April. Q1'26 beat. Turnaround intact.
A17: • Buffett-style: defensive moat + secular tailwind + temp dislocation = Buffett setup
A18: • BIGGEST RISK: regulatory (Medicare risk-coding probes) — watch closely
A20: LEN (+52% upside) — CYCLICAL CONTRARIAN
A21: • Trading at $94 vs intrinsic $143. Stock down 35% on housing slowdown.
A22: • FY25 FCF collapsed to $28M (was $2.27B FY24) — we use cycle-avg $1.5B
A23: • Aggressive buybacks: $1.7B in FY25 = ~7% share count reduction
A24: • Buffett historically buys cyclicals at trough — housing under-supplied long-term
... A75: AVOID: NVDA at current price — watchlist for material pullback

Sheet Portfolio DCF
A1: Portfolio DCF — 5 Names + DPZ Reference (Buffett Framework)
A2: Per-share owner-earnings model. All inputs blue, formulas black, links green. Currency local to each name.
A4: Ticker | B4: DPZ | C4: UNH | D4: 1810.HK | E4: LEN | F4: POOL | G4: TTE | H4: NVDA
A5: Currency | B5: USD | C5: USD | D5: HKD | E5: USD | F5: USD | G5: USD | H5: USD
A7: MARKET DATA & INPUTS
A8: Current price (local ccy) | B8: 372 | C8: 354 | D8: 31.2 | E8: 94 | F8: 234 | G8: 89.79 | H8: 216.61
A9: Diluted shares (M) | B9: 33.6 | C9: 908.2 | D9: 25500 | E9: 247.6 | F9: 36.7 | G9: 2130 | H9: 24300
A10: Market cap (local M) | B10: =B8*B9 | C10: =C8*C9 | D10: =D8*D9 | E10: =E8*E9 | F10: =F8*F9 | G10: =G8*G9 | H10: =H8*H9
A11: Net debt (local M) | B11: 4784 | C11: 80000 | D11: -100000 | E11: 2100 | F11: 1175 | G11: 20200 | H11: -38000
A12: Enterprise value | B12: =B10+B11 | C12: =C10+C11 | D12: =D10+D11 | E12: =E10+E11 | F12: =F10+F11 | G12: =G10+G11 | H12: =H10+H11
A14: BUSINESS METRICS (LTM, local M) | D14: (Xiaomi: RMB→HKD ~×1.1)
A15: Revenue (LTM) | B15: 5008 | C15: 449710 | D15: 457290 | E15: 34200 | F15: 5300 | G15: 200000 | H15: 215900
A16: Free Cash Flow (LTM) | B16: 680 | C16: 17400 | D16: 32000 | E16: 28 | F16: 336 | G16: 11400 | H16: 72000
A17: Normalized FCF (cycle-avg) | B17: 600 | C17: 24000 | D17: 35000 | E17: 1500 | F17: 380 | G17: 13000 | H17: 95000
A18: FCF margin (normalized) | B18: =B17/B15 | C18: =C17/C15 | D18: =D17/D15 | E18: =E17/E15 | F18: =F17/F15 | G18: =G17/G15 | H18: =H17/H15
A20: BUFFETT-STYLE ASSUMPTIONS
A21: FCF growth Y1-5 (high-vis) | B21: 0.05 | C21: 0.06 | D21: 0.12 | E21: 0.05 | F21: 0.05 | G21: 0.03 | H21: 0.18
A22: FCF growth Y6-10 (fade) | B22: 0.04 | C22: 0.05 | D22: 0.08 | E22: 0.04 | F22: 0.05 | G22: 0.02 | H22: 0.08
A23: FCF growth Y11-15 (mature) | B23: 0.03 | C23: 0.04 | D23: 0.05 | E23: 0.03 | F23: 0.04 | G23: 0.01 | H23: 0.04
A24: Discount rate (Buffett hurdle) | B24: 0.09 | C24: 0.09 | D24: 0.11 | E24: 0.1 | F24: 0.09 | G24: 0.09 | H24: 0.1
A25: Terminal growth | B25: 0.025 | C25: 0.025 | D25: 0.03 | E25: 0.02 | F25: 0.025 | G25: 0 | H25: 0.03
A26: Annual buyback yield (assumed) | B26: 0.034 | C26: 0.02 | D26: 0 | E26: 0.04 | F26: 0.03 | G26: 0.035 | H26: 0.018
A29: VALUATION ENGINE (15-yr per-share DCF)
A30: Year #
A31: Y1 | B31: =B$17*(1+B$21) | C31: =C$17*(1+C$21) | D31: =D$17*(1+D$21) | E31: =E$17*(1+E$21) | F31: =F$17*(1+F$21) | G31: =G$17*(1+G$21) | H31: =H$17*(1+H$21)
A32: Y2 | B32: =B31*(1+B$21) | C32: =C31*(1+C$21) | D32: =D31*(1+D$21) | E32: =E31*(1+E$21) | F32: =F31*(1+F$21) | G32: =G31*(1+G$21) | H32: =H31*(1+H$21)
A33: Y3 | B33: =B32*(1+B$21) | C33: =C32*(1+C$21) | D33: =D32*(1+D$21) | E33: =E32*(1+E$21) | F33: =F32*(1+F$21) | G33: =G32*(1+G$21) | H33: =H32*(1+H$21)
A34: Y4 | B34: =B33*(1+B$21) | C34: =C33*(1+C$21) | D34: =D33*(1+D$21) | E34: =E33*(1+E$21) | F34: =F33*(1+F$21) | G34: =G33*(1+G$21) | H34: =H33*(1+H$21)
A35: Y5 | B35: =B34*(1+B$21) | C35: =C34*(1+C$21) | D35: =D34*(1+D$21) | E35: =E34*(1+E$21) | F35: =F34*(1+F$21) | G35: =G34*(1+G$21) | H35: =H34*(1+H$21)
A36: Y6 | B36: =B35*(1+B$22) | C36: =C35*(1+C$22) | D36: =D35*(1+D$22) | E36: =E35*(1+E$22) | F36: =F35*(1+F$22) | G36: =G35*(1+G$22) | H36: =H35*(1+H$22)
A37: Y7 | B37: =B36*(1+B$22) | C37: =C36*(1+C$22) | D37: =D36*(1+D$22) | E37: =E36*(1+E$22) | F37: =F36*(1+F$22) | G37: =G36*(1+G$22) | H37: =H36*(1+H$22)
A38: Y8 | B38: =B37*(1+B$22) | C38: =C37*(1+C$22) | D38: =D37*(1+D$22) | E38: =E37*(1+E$22) | F38: =F37*(1+F$22) | G38: =G37*(1+G$22) | H38: =H37*(1+H$22)
A39: Y9 | B39: =B38*(1+B$22) | C39: =C38*(1+C$22) | D39: =D38*(1+D$22) | E39: =E38*(1+E$22) | F39: =F38*(1+F$22) | G39: =G38*(1+G$22) | H39: =H38*(1+H$22)
A40: Y10 | B40: =B39*(1+B$22) | C40: =C39*(1+C$22) | D40: =D39*(1+D$22) | E40: =E39*(1+E$22) | F40: =F39*(1+F$22) | G40: =G39*(1+G$22) | H40: =H39*(1+H$22)
A41: Y11 | B41: =B40*(1+B$23) | C41: =C40*(1+C$23) | D41: =D40*(1+D$23) | E41: =E40*(1+E$23) | F41: =F40*(1+F$23) | G41: =G40*(1+G$23) | H41: =H40*(1+H$23)
A42: Y12 | B42: =B41*(1+B$23) | C42: =C41*(1+C$23) | D42: =D41*(1+D$23) | E42: =E41*(1+E$23) | F42: =F41*(1+F$23) | G42: =G41*(1+G$23) | H42: =H41*(1+H$23)
A43: Y13 | B43: =B42*(1+B$23) | C43: =C42*(1+C$23) | D43: =D42*(1+D$23) | E43: =E42*(1+E$23) | F43: =F42*(1+F$23) | G43: =G42*(1+G$23) | H43: =H42*(1+H$23)
A44: Y14 | B44: =B43*(1+B$23) | C44: =C43*(1+C$23) | D44: =D43*(1+D$23) | E44: =E43*(1+E$23) | F44: =F43*(1+F$23) | G44: =G43*(1+G$23) | H44: =H43*(1+H$23)
A45: Y15 | B45: =B44*(1+B$23) | C45: =C44*(1+C$23) | D45: =D44*(1+D$23) | E45: =E44*(1+E$23) | F45: =F44*(1+F$23) | G45: =G44*(1+G$23) | H45: =H44*(1+H$23)
A47: VALUATION SUMMARY
...

Sheet SpaceX DCF
A1: SpaceX (SPCX) — DCF Valuation Model
A2: Pre-IPO 2026 | Consolidated: Starlink + Launch + xAI/SpaceXAI | FYE Dec
A4: Case Selector (1=Bear, 2=Base, 3=Bull) | B4: 2
A5: Selected Case | B5: =IF(B4=1,"Bear",IF(B4=2,"Base","Bull"))
A7: MARKET DATA & KEY INPUTS
A8: Diluted Shares Outstanding (B, post 5-for-1 split) | B8: 5
A9: Insider Sale Price Dec 2025 ($/sh, post-split) | B9: =421.06/5
A10: Net Debt ($B) | B10: ='SpaceX WACC'!B20
A11: WACC | B11: ='SpaceX WACC'!B26
A12: Tax Rate | B12: ='SpaceX WACC'!B13
A14: PROJECTION YEARS | C14: FY2025A | D14: FY2026E | E14: FY2027E | F14: FY2028E | G14: FY2029E | H14: FY2030E
A16: BEAR CASE ASSUMPTIONS
A17: Starlink Revenue Growth % | D17: 0.4 | E17: 0.25 | F17: 0.15 | G17: 0.08 | H17: 0.05
A18: Launch Revenue Growth % | D18: 0.05 | E18: 0.05 | F18: 0.04 | G18: 0.03 | H18: 0.03
A19: xAI/Other Revenue Growth % | D19: 0.3 | E19: 0.2 | F19: 0.1 | G19: 0.05 | H19: 0.05
A20: EBIT Margin % | D20: 0.05 | E20: 0.08 | F20: 0.1 | G20: 0.12 | H20: 0.13
A21: Terminal Growth Rate | D21: 0.025
A23: BASE CASE ASSUMPTIONS
A24: Starlink Revenue Growth % | D24: 0.25 | E24: 0.2 | F24: 0.15 | G24: 0.1 | H24: 0.08
A25: Launch Revenue Growth % | D25: 0.1 | E25: 0.1 | F25: 0.08 | G25: 0.06 | H25: 0.05
A26: xAI/Other Revenue Growth % | D26: 0.5 | E26: 0.35 | F26: 0.2 | G26: 0.12 | H26: 0.08
A27: EBIT Margin % | D27: 0.08 | E27: 0.13 | F27: 0.17 | G27: 0.2 | H27: 0.22
A28: Terminal Growth Rate | D28: 0.03
A30: BULL CASE ASSUMPTIONS
A31: Starlink Revenue Growth % | D31: 0.6 | E31: 0.45 | F31: 0.3 | G31: 0.2 | H31: 0.12
A32: Launch Revenue Growth % | D32: 0.15 | E32: 0.15 | F32: 0.12 | G32: 0.1 | H32: 0.08
A33: xAI/Other Revenue Growth % | D33: 0.8 | E33: 0.5 | F33: 0.3 | G33: 0.2 | H33: 0.12
A34: EBIT Margin % | D34: 0.1 | E34: 0.16 | F34: 0.22 | G34: 0.26 | H34: 0.28
A35: Terminal Growth Rate | D35: 0.035
A37: ACTIVE CASE (auto-pulled) | D37: ACTIVE CASE (auto-pulled)
A38: Starlink Growth | D38: =CHOOSE($B$4,D17,D24,D31) | E38: =CHOOSE($B$4,E17,E24,E31) | F38: =CHOOSE($B$4,F17,F24,F31) | G38: =CHOOSE($B$4,G17,G24,G31) | H38: =CHOOSE($B$4,H17,H24,H31)
A39: Launch Growth | D39: =CHOOSE($B$4,D18,D25,D32) | E39: =CHOOSE($B$4,E18,E25,E32) | F39: =CHOOSE($B$4,F18,F25,F32) | G39: =CHOOSE($B$4,G18,G25,G32) | H39: =CHOOSE($B$4,H18,H25,H32)
A40: xAI/Other Growth | D40: =CHOOSE($B$4,D19,D26,D33) | E40: =CHOOSE($B$4,E19,E26,E33) | F40: =CHOOSE($B$4,F19,F26,F33) | G40: =CHOOSE($B$4,G19,G26,G33) | H40: =CHOOSE($B$4,H19,H26,H33)
A41: EBIT Margin | D41: =CHOOSE($B$4,D20,D27,D34) | E41: =CHOOSE($B$4,E20,E27,E34) | F41: =CHOOSE($B$4,F20,F27,F34) | G41: =CHOOSE($B$4,G20,G27,G34) | H41: =CHOOSE($B$4,H20,H27,H34)
A42: Terminal Growth | D42: =CHOOSE($B$4,$D$21,$D$28,$D$35)
A43: D&A % of Revenue | D43: 0.12 | E43: =$D$43 | F43: =$D$43 | G43: =$D$43 | H43: =$D$43
A44: CapEx % of Revenue | D44: 0.18 | E44: =$D$44 | F44: =$D$44 | G44: =$D$44 | H44: =$D$44
A45: Δ NWC % of ΔRev | D45: 0.05 | E45: =$D$45 | F45: =$D$45 | G45: =$D$45 | H45: =$D$45
A47: REVENUE BUILD ($B)
A48: Starlink Revenue | C48: 11.4 | D48: =C48*(1+D38) | E48: =D48*(1+E38) | F48: =E48*(1+F38) | G48: =F48*(1+G38) | H48: =G48*(1+H38)
...

Sheet SpaceX WACC
A1: SpaceX — Weighted Average Cost of Capital
A2: Pre-IPO consolidated entity (incl. Starlink, Launch, xAI/SpaceXAI)
A4: COST OF EQUITY (CAPM)
A5: Risk-Free Rate (10Y UST) | B5: 0.0425
A6: Equity Risk Premium | B6: 0.055
A7: Beta (peer-derived, levered) | B7: 1.4
A8: Country/Size Premium | B8: 0.005
A9: Cost of Equity | B9: =B5+B7*B6+B8
A11: COST OF DEBT
A12: Pre-Tax Cost of Debt | B12: 0.065
A13: Tax Rate | B13: 0.21
A14: After-Tax Cost of Debt | B14: =B12*(1-B13)
A16: CAPITAL STRUCTURE (at IPO)
A17: Market Cap at IPO ($B) | B17: 1750
A18: Total Debt ($B) | B18: 5
A19: Cash & Equivalents ($B) | B19: 3
A20: Net Debt ($B) | B20: =B18-B19
A21: Enterprise Value ($B) | B21: =B17+B20
A22: Equity Weight | B22: =B17/B21
A23: Debt Weight | B23: =B20/B21
A25: WACC
A26: WACC | B26: =B9*B22+B14*B23

Sheet SpaceX IPO Compare
A1: SpaceX — Intrinsic Value vs Broker IPO Price
A2: Change Case Selector on 'SpaceX DCF'!B4 to toggle Bear (1) / Base (2) / Bull (3)
A4: VALUATION SUMMARY (Active Case)
A5: Active Case | B5: ='SpaceX DCF'!B5
A6: Enterprise Value ($B) | B6: ='SpaceX DCF'!B80
A7: Equity Value ($B) | B7: ='SpaceX DCF'!B82
A8: Implied Share Price ($) | B8: ='SpaceX DCF'!B84
A10: BROKER IPO PRICE BENCHMARKS
A11: Scenario | B11: Valuation ($B) | C11: Price/Share ($) | D11: EV/2025 Rev (x) | E11: vs Intrinsic
A12: Insider Sale (Dec 2025) | B12: 800 | C12: =B12/'SpaceX DCF'!$B$8 | D12: =B12/'SpaceX DCF'!$C$51 | E12: ='SpaceX DCF'!$B$84/C12-1
A13: TechCrunch/WSJ Base IPO Target | B13: 1750 | C13: =B13/'SpaceX DCF'!$B$8 | D13: =B13/'SpaceX DCF'!$C$51 | E13: ='SpaceX DCF'!$B$84/C13-1
A14: Bloomberg Stretch IPO Target | B14: 2000 | C14: =B14/'SpaceX DCF'!$B$8 | D14: =B14/'SpaceX DCF'!$C$51 | E14: ='SpaceX DCF'!$B$84/C14-1
A16: INTERPRETATION
A17: Base case DCF (Starlink to $22B by FY30, Launch +3-5%/yr) yields ~$6.50/share intrinsic value.
A18: Broker IPO price of $350 (at $1.75T) implies a 98% premium to standalone DCF.
A19: This gap reflects:
A20: 1) Starship/Mars option value (not modeled in 5-year FCF horizon)
A21: 2) xAI/SpaceXAI long-term AI infrastructure optionality
A22: 3) Scarcity premium - the only listed pure-play LEO/launch leader
A23: 4) Passive index demand if added to S&P 500 / Nasdaq-100 fast-entry
A24: 5) Trading-multiple-based pricing (~87x P/S 2026E) vs intrinsic DCF
A26: EV/Sales context: $1.75T = ~94x 2025 revenue ($18.7B) - more than 2x Nvidia AI-peak multiple.
A27: For DCF to support $350/share, Starlink must reach ~$60-80B revenue or terminal margins ~35-40%.
A29: RECOMMENDATION
... A34: See sensitivity tables on 'SpaceX DCF' (rows 91-107) for the assumption combinations needed to close the gap.

Sheet DPZ Summary
A1: Domino's Pizza (DPZ) — Valuation Summary
A2: Why Buffett bought at $437 — the standard DCF is missing buybacks
A4: THE PUZZLE YOU IDENTIFIED
A5: Standard 15Y FCF DCF → implied price | B5: ='DPZ DCF'!B57
A6: Current market price | B6: ='DPZ DCF'!B5
A7: Buffett purchased at | B7: 437
A8: Standard DCF says current price is overvalued by: | B8: =B6/B5-1
A10: WHAT THE STANDARD DCF MISSES
A11: 1. Capital allocation (buybacks)
A12: DPZ retires ~3-4% of shares per year
A13: $1.46B buyback authorization (Apr 2026 = $1B new + $459.7M existing)
A14: Per-share FCF grows much faster than total FCF
A16: 2. Negative book equity is a feature, not a bug
A17: Stockholders' deficit of -$3.97B reflects $7B+ of cumulative buybacks
A18: Capital-light franchise model (99% franchised) needs minimal equity
A19: ROIC is enormous because invested capital is tiny
A21: 3. Defensive moat — lower required return
A22: Beta ~0.7, recession-resistant, 99% franchised → capital-light royalty stream
A23: Pricing power: low-cost meal occasion, scale advantage in supply chain
A25: PER-SHARE OWNER EARNINGS MODEL (Buffett's framework)
A26: FCF per share today (LTM Q1'26) | B26: ='Per-Share Model'!B7
A27: Annual buyback yield | B27: ='Per-Share Model'!B12
A28: Dividend yield | B28: ='Per-Share Model'!B13
A29: Total shareholder yield | B29: ='Per-Share Model'!B14
A31: Per-share intrinsic value (15Y, 9% disc, 2.5% term) | B31: ='Per-Share Model'!B38
A33: VS THE TWO REFERENCE POINTS
A34: Upside vs current price ($372) | B34: =B31/B6-1
A35: Margin of safety vs Buffett's $437 | B35: =B31/B7-1
A37: CONCLUSION
A38: Buffett did NOT buy on a standard DCF — he bought a per-share compounding machine.
A39: At $437, Buffett got DPZ at ~fair value of intrinsic per-share, with the buyback engine
A40: doing the heavy lifting on returns. At $372 today, you have ~16% upside before
A41: even counting the buybacks accelerating with the new $1B authorization.
A43: TODAY'S Q1'26 EARNINGS (Apr 27, 2026)
A44: Q1 EPS | B44: 4.13
A45: Q1 Revenue | B45: 1150.6
A46: NEW $1B buyback authorization announced today | B46: + existing $459.7M = $1.46B total firepower
A47: Implication: Q1 was a slight miss but BUYBACK was a clear bullish signal.
A48: Mgmt is signaling confidence in the per-share compounding model.

Sheet DPZ DCF
A1: 8
A2: Date: April 27, 2026 | FYE: Late December | All $ in millions except per-share
A4: MARKET DATA
A5: Current price | B5: =WACC!B16
A6: Diluted shares (M) | B6: =WACC!B17
A7: Market cap ($M) | B7: =B5*B6
A8: Net debt ($M) | B8: =WACC!B21
A9: Buffett purchase price (Q3 2024) | B9: 437
A11: HISTORICAL FINANCIALS ($M)
A12: Item | B12: FY2023 | C12: FY2024 | D12: FY2025 | E12: Q1'26 LTM*
A13: Revenue | B13: 4479 | C13: 4711 | D13: 4941 | E13: 5008
A14: Revenue growth % | C14: =C13/B13-1 | D14: =D13/C13-1 | E14: =E13/D13-1
A15: EBIT (Income from operations) | B15: 818 | C15: 879 | D15: 954 | E15: 977
A16: EBIT margin % | B16: =B15/B13 | C16: =C15/C13 | D16: =D15/D13 | E16: =E15/E13
A17: Net income | B17: 519 | C17: 584 | D17: 602 | E17: 600
A18: Operating cash flow | B18: 591 | C18: 625 | D18: 792 | E18: 800
A19: CapEx | B19: 105 | C19: 113 | D19: 121 | E19: 120
A20: Free Cash Flow | B20: =B18-B19 | C20: =C18-C19 | D20: =D18-D19 | E20: =E18-E19
A21: FCF margin % | B21: =B20/B13 | C21: =C20/C13 | D21: =D20/D13 | E21: =E20/E13
A23: BUFFETT-STYLE ASSUMPTIONS (Conservative)
A24: Revenue growth Y1-5 (high-vis) | B24: 0.05
A25: Revenue growth Y6-10 (fade) | B25: 0.04
A26: Revenue growth Y11-15 (mature) | B26: 0.03
A27: Steady-state FCF margin | B27: 0.13
A28: WACC (discount rate) | B28: =WACC!B27
A29: Buffett discount rate (alt) | B29: 0.09
A30: Terminal growth rate | B30: 0.025
A31: Use which discount rate? | B31: Buffett 9%
A32: Selected discount rate | B32: =IF(B31="WACC",B28,B29)
A34: 15-YEAR FCF PROJECTION ($M)
A35: Item | B35: FY26E | C35: FY27E | D35: FY28E | E35: FY29E | F35: FY30E | G35: FY31E | H35: FY32E | I35: FY33E | J35: FY34E | K35: FY35E | L35: FY36E | M35: FY37E | N35: FY38E | O35: FY39E | P35: FY40E
A36: Year # | B36: 1 | C36: 2 | D36: 3 | E36: 4 | F36: 5 | G36: 6 | H36: 7 | I36: 8 | J36: 9 | K36: 10 | L36: 11 | M36: 12 | N36: 13 | O36: 14 | P36: 15
A37: Revenue growth % | B37: =IF(B36<=5,$B$24,IF(B36<=10,$B$25,$B$26)) | C37: =IF(C36<=5,$B$24,IF(C36<=10,$B$25,$B$26)) | D37: =IF(D36<=5,$B$24,IF(D36<=10,$B$25,$B$26)) | E37: =IF(E36<=5,$B$24,IF(E36<=10,$B$25,$B$26)) | F37: =IF(F36<=5,$B$24,IF(F36<=10,$B$25,$B$26)) | G37: =IF(G36<=5,$B$24,IF(G36<=10,$B$25,$B$26)) | H37: =IF(H36<=5,$B$24,IF(H36<=10,$B$25,$B$26)) | I37: =IF(I36<=5,$B$24,IF(I36<=10,$B$25,$B$26)) | ... P37: =IF(P36<=5,$B$24,IF(P36<=10,$B$25,$B$26))
A38: Revenue | B38: =$E$13*(1+B37) | C38: =B38*(1+C37) | D38: =C38*(1+D37) | E38: =D38*(1+E37) | F38: =E38*(1+F37) | G38: =F38*(1+G37) | H38: =G38*(1+H37) | I38: =H38*(1+I37) | J38: =I38*(1+J37) | ... P38: =O38*(1+P37)
A39: FCF margin % | B39: =$B$27 | C39: =$B$27 | D39: =$B$27 | E39: =$B$27 | F39: =$B$27 | G39: =$B$27 | H39: =$B$27 | I39: =$B$27 | ... P39: =$B$27
A40: Free Cash Flow | B40: =B38*B39 | C40: =C38*C39 | D40: =D38*D39 | E40: =E38*E39 | F40: =F38*F39 | G40: =G38*G39 | H40: =H38*H39 | I40: =I38*I39 | ... P40: =P38*P39
A41: Discount period (mid-yr) | B41: =B36-0.5 | C41: =C36-0.5 | D41: =D36-0.5 | E41: =E36-0.5 | F41: =F36-0.5 | G41: =G36-0.5 | H41: =H36-0.5 | I41: =I36-0.5 | ... P41: =P36-0.5
A42: Discount factor | B42: =1/(1+$B$32)^B41 | C42: =1/(1+$B$32)^C41 | D42: =1/(1+$B$32)^D41 | E42: =1/(1+$B$32)^E41 | F42: =1/(1+$B$32)^F41 | G42: =1/(1+$B$32)^G41 | H42: =1/(1+$B$32)^H41 | I42: =1/(1+$B$32)^I41 | ... P42: =1/(1+$B$32)^P41
A43: PV of FCF | B43: =B40*B42 | C43: =C40*C42 | D43: =D40*D42 | E43: =E40*E42 | F43: =F40*F42 | G43: =G40*G42 | H43: =H40*H42 | I43: =I40*I42 | ... P43: =P40*P42
A45: TERMINAL VALUE & VALUATION SUMMARY
...

Sheet Per-Share Model
A1: DPZ — PER-SHARE OWNER EARNINGS MODEL (Why Buffett Bought)
A2: Key insight: DPZ retires ~3-4% of shares annually. Per-share FCF grows much faster than total FCF.
A4: STARTING POINT (LTM as of Q1'26)
A5: LTM Free Cash Flow ($M) | B5: ='DPZ DCF'!E20
A6: Diluted shares (M) | B6: ='DPZ DCF'!B6
A7: FCF per share (LTM) | B7: =B5/B6
A9: BUYBACK YIELD
A10: Total buyback authorization (Apr 2026) | B10: 1460
A11: Annual buyback pace ($M, conservative) | B11: 500
A12: Implied annual share retirement % | B12: =B11/('DPZ DCF'!B7)
A13: Dividend yield (current) | B13: 0.0214
A14: Total shareholder yield (FCF yield + buyback) | B14: =B7/'DPZ DCF'!B5+B12
A16: 15-YEAR PER-SHARE FCF PROJECTION
A17: Item | B17: FY26E | C17: FY27E | D17: FY28E | E17: FY29E | F17: FY30E | G17: FY31E | H17: FY32E | I17: FY33E | J17: FY34E | K17: FY35E | L17: FY36E | M17: FY37E | N17: FY38E | O17: FY39E | P17: FY40E
A18: Year # | B18: 1 | C18: 2 | D18: 3 | E18: 4 | F18: 5 | G18: 6 | H18: 7 | I18: 8 | J18: 9 | K18: 10 | L18: 11 | M18: 12 | N18: 13 | O18: 14 | P18: 15
A19: Total FCF growth % | B19: =IF(B18<=5,'DPZ DCF'!$B$24,IF(B18<=10,'DPZ DCF'!$B$25,'DPZ DCF'!$B$26)) | C19: =IF(C18<=5,'DPZ DCF'!$B$24,IF(C18<=10,'DPZ DCF'!$B$25,'DPZ DCF'!$B$26)) | D19: =IF(D18<=5,'DPZ DCF'!$B$24,IF(D18<=10,'DPZ DCF'!$B$25,'DPZ DCF'!$B$26)) | E19: =IF(E18<=5,'DPZ DCF'!$B$24,IF(E18<=10,'DPZ DCF'!$B$25,'DPZ DCF'!$B$26)) | F19: =IF(F18<=5,'DPZ DCF'!$B$24,IF(F18<=10,'DPZ DCF'!$B$25,'DPZ DCF'!$B$26)) | G19: =IF(G18<=5,'DPZ DCF'!$B$24,IF(G18<=10,'DPZ DCF'!$B$25,'DPZ DCF'!$B$26)) | H19: =IF(H18<=5,'DPZ DCF'!$B$24,IF(H18<=10,'DPZ DCF'!$B$25,'DPZ DCF'!$B$26)) | I19: =IF(I18<=5,'DPZ DCF'!$B$24,IF(I18<=10,'DPZ DCF'!$B$25,'DPZ DCF'!$B$26)) | ... P19: =IF(P18<=5,'DPZ DCF'!$B$24,IF(P18<=10,'DPZ DCF'!$B$25,'DPZ DCF'!$B$26))
A20: Total FCF ($M) | B20: =$B$5*(1+B19) | C20: =B20*(1+C19) | D20: =C20*(1+D19) | E20: =D20*(1+E19) | F20: =E20*(1+F19) | G20: =F20*(1+G19) | H20: =G20*(1+H19) | I20: =H20*(1+I19) | J20: =I20*(1+J19) | ... P20: =O20*(1+P19)
A21: Share retirement % | B21: =$B$12*0.85 | C21: =$B$12*0.85 | D21: =$B$12*0.85 | E21: =$B$12*0.85 | F21: =$B$12*0.85 | G21: =$B$12*0.85 | H21: =$B$12*0.85 | I21: =$B$12*0.85 | ... P21: =$B$12*0.85
A22: Shares outstanding (M) | B22: =$B$6*(1-B21) | C22: =B22*(1-C21) | D22: =C22*(1-D21) | E22: =D22*(1-E21) | F22: =E22*(1-F21) | G22: =F22*(1-G21) | H22: =G22*(1-H21) | I22: =H22*(1-I21) | J22: =I22*(1-J21) | ... P22: =O22*(1-P21)
A23: FCF per share | B23: =B20/B22 | C23: =C20/C22 | D23: =D20/D22 | E23: =E20/E22 | F23: =F20/F22 | G23: =G20/G22 | H23: =H20/H22 | I23: =I20/I22 | ... P23: =P20/P22
A24: per-share FCF growth | B24: — | C24: =C23/B23-1 | D24: =D23/C23-1 | E24: =E23/D23-1 | F24: =F23/E23-1 | G24: =G23/F23-1 | H24: =H23/G23-1 | I24: =I23/H23-1 | J24: =J23/I23-1 | ... P24: =P23/O23-1
A25: Discount factor (9%) | B25: =1/(1+'DPZ DCF'!$B$32)^(B18-0.5) | C25: =1/(1+'DPZ DCF'!$B$32)^(C18-0.5) | D25: =1/(1+'DPZ DCF'!$B$32)^(D18-0.5) | E25: =1/(1+'DPZ DCF'!$B$32)^(E18-0.5) | F25: =1/(1+'DPZ DCF'!$B$32)^(F18-0.5) | G25: =1/(1+'DPZ DCF'!$B$32)^(G18-0.5) | H25: =1/(1+'DPZ DCF'!$B$32)^(H18-0.5) | I25: =1/(1+'DPZ DCF'!$B$32)^(I18-0.5) | ... P25: =1/(1+'DPZ DCF'!$B$32)^(P18-0.5)
A26: PV of FCF/share | B26: =B23*B25 | C26: =C23*C25 | D26: =D23*D25 | E26: =E23*E25 | F26: =F23*F25 | G26: =G23*G25 | H26: =H23*H25 | I26: =I23*I25 | ... P26: =P23*P25
A28: PER-SHARE VALUATION SUMMARY
A29: Terminal year FCF/share (Y15) | B29: =P23
A30: Terminal growth | B30: ='DPZ DCF'!B30
A31: Discount rate | B31: ='DPZ DCF'!B32
A32: Terminal value per share at Y15 | B32: =B29*(1+B30)/(B31-B30)
A33: PV of terminal value per share | B33: =B32*P25
A35: Sum PV of FCF/share (Y1-15) | B35: =SUM(B26:P26)
A36: (+) PV terminal value/share | B36: =B33
A37: (−) Net debt per share (current) | B37: =-'DPZ DCF'!B8/B6
A38: Intrinsic value per share | B38: =B35+B36+B37
A40: Current price | B40: ='DPZ DCF'!B5
A41: Buffett's purchase price | B41: ='DPZ DCF'!B9
A42: Upside vs current ($372) | B42: =B38/B40-1
A43: Margin of safety vs Buffett ($437) | B43: =B38/B41-1
A46: SENSITIVITY: Intrinsic Value/Share — Discount Rate vs Terminal Growth
A48: Discount \ Term g → | B48: 0.015 | C48: 0.02 | D48: 0.025 | E48: 0.03 | F48: 0.035
A49: 0.07 | B49: {=SUMPRODUCT($B$23:$P$23, 1/(1+$A49)^($B$18:$P$18-0.5)) + ($P$23*(1+B$48)/($A49-B$48))/((1+$A49)^14.5) - 'DPZ DCF'!$B$8/$B$6} | C49: {=SUMPRODUCT($B$23:$P$23, 1/(1+$A49)^($B$18:$P$18-0.5)) + ($P$23*(1+C$48)/($A49-C$48))/((1+$A49)^14.5) - 'DPZ DCF'!$B$8/$B$6} | D49: {=SUMPRODUCT($B$23:$P$23, 1/(1+$A49)^($B$18:$P$18-0.5)) + ($P$23*(1+D$48)/($A49-D$48))/((1+$A49)^14.5) - 'DPZ DCF'!$B$8/$B$6} | E49: {=SUMPRODUCT($B$23:$P$23, 1/(1+$A49)^($B$18:$P$18-0.5)) + ($P$23*(1+E$48)/($A49-E$48))/((1+$A49)^14.5) - 'DPZ DCF'!$B$8/$B$6} | F49: {=SUMPRODUCT($B$23:$P$23, 1/(1+$A49)^($B$18:$P$18-0.5)) + ($P$23*(1+F$48)/($A49-F$48))/((1+$A49)^14.5) - 'DPZ DCF'!$B$8/$B$6}
...

Sheet WACC
A1: DPZ — WACC Calculation
A2: As of April 27, 2026
A4: COST OF EQUITY (CAPM)
A5: Risk-free rate (10Y Treasury) | B5: 0.043
A6: Beta (5Y monthly) | B6: 0.7
A7: Equity Risk Premium | B7: 0.055
A8: Cost of Equity = Rf + β × ERP | B8: =B5+B6*B7
A10: COST OF DEBT
A11: Pre-tax cost of debt (avg coupon) | B11: 0.052
A12: Tax rate | B12: 0.22
A13: After-tax cost of debt | B13: =B11*(1-B12)
A15: CAPITAL STRUCTURE
A16: Share price ($) | B16: 372
A17: Diluted shares (M) | B17: 33.6
A18: Market cap ($M) | B18: =B16*B17
A19: Total debt ($M) | B19: 5000
A20: Cash & restricted cash ($M) | B20: 216
A21: Net debt ($M) | B21: =B19-B20
A22: Enterprise value ($M) | B22: =B18+B21
A24: Equity weight | B24: =B18/B22
A25: Debt weight | B25: =B21/B22
A27: WACC | B27: =B8*B24+B13*B25
A29: Note: Buffett-style — we'll also test 9-10% as a more conservative discount rate.

Sheet Peer Comparison
A1: DPZ vs Peers vs Market Expectations — How Realistic is 5% FCF Growth?
A2: Question: Our DCF assumes 5% revenue/FCF growth Y1-5. Is that conservative, base-case, or aggressive?
A4: QSR PEER GROWTH PROFILE (Consensus FY26-28)
A5: Company | B5: Ticker | C5: Rev Growth FY26E | D5: EPS Growth FY26-28E CAGR | E5: Q4'25 SSS | F5: Business Model | G5: Note
A6: Domino's Pizza | B6: DPZ | C6: 0.055 | D6: 0.102 | E6: 0 | F6: 99% franchised + supply chain | G6: Most aggressive buyback in QSR
A7: Chipotle | B7: CMG | C7: 0.07 | D7: 0.13 | E7: -0.04 | F7: Company-owned | G7: Currently struggling — SSS turned negative
A8: Wingstop | B8: WING | C8: 0.12 | D8: 0.18 | E8: -0.058 | F8: Asset-light franchise | G8: High unit growth offsets weak SSS
A9: Yum! Brands | B9: YUM | C9: 0.05 | D9: 0.09 | E9: 0.04 | F9: Multi-brand franchise | G9: Closest peer to DPZ scale & model
A10: Restaurant Brands | B10: QSR | C10: 0.05 | D10: 0.08 | E10: 0.026 | F10: Multi-brand franchise | G10: BK/THI/Popeyes; mature
A11: McDonald's | B11: MCD | C11: 0.04 | D11: 0.07 | E11: 0.02 | F11: 95% franchised | G11: Most mature comp
A12: Papa John's | B12: PZZA | C12: 0.02 | D12: 0.04 | E12: -0.02 | F12: Franchise | G12: Direct pizza competitor — losing share to DPZ
A14: Restaurants Industry Avg (consensus) | C14: 0.067 | D14: 0.189
A15: US Pizza Foodservice Mkt CAGR 26-31 | C15: 0.0746
A16: DPZ mgmt LT target (US retail sales) | C16: 0.06
A17: DPZ mgmt LT target (op income growth) | D17: 0.07
A19: VERDICT: How likely is 5% FCF growth?
A20: Reference point | B20: Growth Rate | C20: Read
A21: DPZ historical FCF CAGR (FY04-FY25, 21yr) | B21: 0.107 | C21: Actual track record — well above 5%
A22: DPZ historical FCF CAGR (FY15-FY25, 10yr) | B22: 0.118 | C22: More recent 10-yr period even stronger
A23: DPZ historical Revenue CAGR (FY15-FY25, 10yr) | B23: 0.064 | C23: Revenue grew slower than FCF (margin expansion)
A24: Analyst consensus FY26 revenue growth | B24: 0.055 | C24: Matches our 5% assumption — in line
A25: Analyst consensus EPS CAGR FY26-28 | B25: 0.102 | C25: EPS grows ~2x faster than revenue (buyback effect)
A26: Mgmt long-term op income target | B26: 0.07 | C26: Mgmt confidence is above our 5%
A27: US Pizza foodservice market CAGR | B27: 0.0746 | C27: Industry growing faster than 5%
A28: Restaurants industry avg consensus rev | B28: 0.067 | C28: Industry expects 6.7% — we're below
A29: OUR DCF ASSUMPTION (Y1-5) | B29: 0.05 | C29: BELOW all reference points — conservative
A31: PROBABILITY ASSESSMENT
A32: Scenario | B32: Probability | C32: Implied FCF Growth Y1-5
A33: Bear: SSS stagnation, traffic loss, competition | B33: 0.2 | C33: 2-3%
A34: Base: 5% (our model) — conservative vs analyst 5.5%, mgmt 6-7% | B34: 0.55 | C34: 0.05
A35: Bull: hits mgmt LT target of 7%+, regains SSS momentum | B35: 0.25 | C35: 7-9%
A37: BOTTOM LINE
A38: 5% FCF growth is a CONSERVATIVE assumption.
A39: • DPZ delivered 10.7% FCF CAGR over 21 years
A40: • Analyst consensus FY26 = 5.5%; mgmt LT target = 6-7%
A41: • US pizza market CAGR forecast = 7.5%
A42: • Q1'26 was a soft quarter (flat SSS) — but mgmt confidence shown via $1B buyback
A43: • Real risk: GLP-1 drugs, 3rd-party delivery dilution, beef/labor inflation pressuring franchisee economics
A45: What WOULD make 5% wrong on the downside?
A46: 1. Persistent negative SSS (Q1'26 was already flat — watch closely)
...

Sheet Dashboard
A1: S&P 500 Dashboard
A2: Last updated: 2026-10-20 15:02:44 | 482 full / 8 partial / 4 no-data (kept) | 145s elapsed
A3: Total: 494 companies | IV: 15-yr Buffett DCF + geo-risk v4 (Iran ceasefire fragile, Brent $104, S&P 7,500 ATH, fwd P/E 21.2, Fed 3.50-3.75% held 8-4) | BRK Q1 2026 13F (filed May 15): $263B portfolio, 29 positions (-13), 16 exits incl V/MA/UNH/DPZ/HEI/CHTR/AON/POOL/LAMR/ALLE, CVX -35%, STZ -95%, GOOGL TRIPLED to $15.6B, new DAL/GOOG/M. Abel cash $380B
J4: Run: python update_sp500_dashboard.py | M4: ▶ UPDATE DATA | O4: BRK: 13F thru Q4 2025 + Q1 26 earnings ($397B cash) | KHC exit REVERSED | BAC sell 7th qtr | $234M buyback | Abel "core four": AAPL AXP KO MCO
A5: # | B5: Ticker | C5: Company | D5: Industry | E5: Share Price ($) | F5: 1Y Price Change (%) | G5: Market Cap ($B) | H5: Revenue Growth (%) | I5: Gross Margin (%) | J5: P/E | K5: FCF ($M) | L5: Intrinsic Value ($B) | M5: IV vs MCap Discount (%) | N5: P/FCF | O5: BRK? | P5: BRK Pos ($B) | Q5: BRK Net Action | R5: BRK Avg Cost ($) | S5: Activity Detail (2025-Q1 2026)
A6: 1 | B6: MS | C6: Morgan Stanley | D6: Capital Markets | E6: 178.47 | F6: 0.12083149 | G6: 280.29898 | H6: 0.108 | I6: 0.87307 | J6: 14.153053 | K6: — | L6: — | M6: — | N6: — | O6: — | P6: — | Q6: — | R6: — | S6: —
A7: 2 | B7: SCHW | C7: Charles Schwab | D7: Capital Markets | E7: 89.58 | F7: -0.057945132 | G7: 154.9139 | H7: 0.169 | I7: 0.97506 | J7: 15.312821 | K7: — | L7: 58.800668 | M7: -0.62043 | N7: — | O7: — | P7: — | Q7: — | R7: — | S7: —
A8: 3 | B8: O | C8: Realty Income | D8: REIT - Retail | E8: 55.51 | F8: -0.07529569 | G8: 52.52456 | H8: 0.096 | I8: 0.9268 | J8: 40.224636 | K8: 1582.0819 | L8: 6.1463742 | M8: -0.88298095 | N8: 33.199648 | O8: — | P8: — | Q8: — | R8: — | S8: —
A9: 4 | B9: PLD | C9: Prologis | D9: REIT - Industrial | E9: 124.09 | F9: -0.015080571 | G9: 120.62681 | H9: 0.102 | I9: 0.75709 | J9: 27.575554 | K9: — | L9: 21.711072 | M9: -0.82001454 | N9: — | O9: — | P9: — | Q9: — | R9: — | S9: —
A10: 5 | B10: BAC | C10: Bank of America | D10: Banks - Diversified | E10: 50.39 | F10: -0.021933258 | G10: 352.36459 | H10: 0.071 | I10: 0 | J10: 12.026253 | K10: — | L10: 146.9885 | M10: -0.58285112 | N10: — | O10: YES | P10: 25.1 | Q10: Sell | R10: 25.7 | S10: Sold 48.7M Q1-25 → 26.3M Q2 → 50.8M Q4 → Q1-26: TRIMMED <1% (~4M sh) to 513M. 9.5% of portfolio. $ drop mostly price ($55→$49)
A11: 6 | B11: VRSN | C11: VeriSign | D11: Software - Infrastructure | E11: 306.48 | F11: 0.15019143 | G11: 27.705793 | H11: 0.06 | I11: 0.88465 | J11: 33.276875 | K11: 832.8375 | L11: 7.3862498 | M11: -0.73340413 | N11: 33.266744 | O11: YES | P11: 3.2 | Q11: Hold | R11: 27 | S11: Held Q1-Q2-25 → Trimmed Q3-Q4 → Q1-26: UNCHANGED (NOT exited — Kiplinger/Benzinga not in 16-exit list). ~13.5M sh
A12: 7 | B12: COF | C12: Capital One Financial | D12: Credit Services | E12: 199.83 | F12: -0.07933658 | G12: 122.59571 | H12: 11.11 | I12: 0 | J12: 12.834297 | K12: — | L12: 47.679789 | M12: -0.6110811 | N12: — | O12: YES | P12: 2.05 | Q12: Hold | R12: 95 | S12: ~9.9M sh since 2022. Q1-26: UNCHANGED (NOT exited despite Combs-era origin). Held through Combs departure
A13: 8 | B13: ESS | C13: Essex Property Trust | D13: REIT - Residential | E13: 266.65 | F13: 0.017825842 | G13: 18.379168 | H13: 0.031 | I13: 0.68771005 | J13: 41.469673 | K13: 1043.9267 | L13: 2.0062438 | M13: -0.89084142 | N13: 16.414364 | O13: — | P13: — | Q13: — | R13: — | S13: —
A14: 9 | B14: REG | C14: Regency Centers | D14: REIT - Retail | E14: 72.41 | F14: 0.0034645796 | G14: 13.537682 | H14: 0.089 | I14: 0.71539 | J14: 24.380472 | K14: 743.36397 | L14: 2.629481 | M14: -0.80576579 | N14: 17.837505 | O14: — | P14: — | Q14: — | R14: — | S14: —
A15: 10 | B15: V | C15: Visa | D15: Credit Services | E15: 402.92 | F15: 0.16045046 | G15: 756.42398 | H15: 0.144 | I15: 0.97725 | J15: 34.291065 | K15: 20404.001 | L15: 52.817226 | M15: -0.9301751 | N15: 33.651297 | O15: SOLD | P15: — | Q15: Sold | R15: 130 | S15: Held unchanged 2025 → Q1-26: ABEL FULLY EXITED. Combs-era position (since 2011). Symbolic: "no longer a fan of payments processors" (Kiplinger)
A16: 11 | B16: EXR | C16: Extra Space Storage | D16: REIT - Industrial | E16: 138.18 | F16: -0.08216542 | G16: 30.496676 | H16: 0.038 | I16: 0.74919 | J16: 30.503307 | K16: 1499.4376 | L16: 4.6436544 | M16: -0.84773244 | N16: 19.469452 | O16: — | P16: — | Q16: — | R16: — | S16: —
A17: 12 | B17: GS | C17: Goldman Sachs Group | D17: Capital Markets | E17: 875.78 | F17: 0.15389073 | G17: 255.00208 | H17: 0.233 | I17: 0.81287 | J17: 12.592092 | K17: — | L17: 103.35889 | M17: -0.59467431 | N17: — | O17: — | P17: — | Q17: — | R17: — | S17: —
A18: 13 | B18: SYF | C18: Synchrony Finl | D18: Credit Services | E18: 74.24 | F18: 0.003243208 | G18: 24.155531 | H18: 0.006 | I18: 0 | J18: 7.598771 | K18: — | L18: 17.08696 | M18: -0.29262745 | N18: — | O18: — | P18: — | Q18: — | R18: — | S18: —
A19: 14 | B19: SPG | C19: Simon Property Group | D19: REIT - Retail | E19: 202.49 | F19: 0.13300133 | G19: 76.86996 | H19: 0.195 | I19: 0.81426 | J19: 14.29005 | K19: 2595.2712 | L19: 6.352417 | M19: -0.91736151 | N19: 25.244355 | O19: — | P19: — | Q19: — | R19: — | S19: —
A20: 15 | B20: AVB | C20: AvalonBay Communities | D20: REIT - Residential | E20: 184.06 | F20: -0.008827567 | G20: 26.283393 | H20: 0.023 | I20: 0.62721 | J20: 25.248285 | K20: 1409.1441 | L20: 5.0274582 | M20: -0.80872111 | N20: 18.652027 | O20: — | P20: — | Q20: — | R20: — | S20: —
A21: 16 | B21: PSA | C21: Public Storage | D21: REIT - Industrial | E21: 295.69 | F21: -0.04080838 | G21: 55.250354 | H21: 0.033 | I21: 0.7442 | J21: 28.241642 | K21: 2334.2403 | L21: 5.688993 | M21: -0.89703246 | N21: 23.669524 | O21: — | P21: — | Q21: — | R21: — | S21: —
A22: 17 | B22: KIM | C22: Kimco Realty | D22: REIT - Retail | E22: 22.69 | F22: 0.021611929 | G22: 15.220212 | H22: 0.049 | I22: 0.68933 | J22: 26.694117 | K22: 871.48339 | L22: 2.8744259 | M22: -0.81114416 | N22: 17.464717 | O22: — | P22: — | Q22: — | R22: — | S22: —
A23: 18 | B23: CME | C23: CME Group | D23: Financial Data & Stock Exchanges | E23: 293.53 | F23: 0.092773914 | G23: 105.5473 | H23: 0.008 | I23: 1 | J23: 24.896523 | K23: 2909.0125 | L23: 22.398196 | M23: -0.78778997 | N23: 36.282546 | O23: — | P23: — | Q23: — | R23: — | S23: —
A24: 19 | B24: MAA | C24: Mid-America Apartment | D24: REIT - Residential | E24: 115.8 | F24: -0.13193405 | G24: 13.818025 | H24: 0.01 | I24: 0.58392 | J24: 33.85965 | K24: 921.18227 | L24: 1.8788979 | M24: -0.86402559 | N24: 14.630503 | O24: — | P24: — | Q24: — | R24: — | S24: —
A25: 20 | B25: STT | C25: State Street | D25: Asset Management | E25: 165.43 | F25: 0.44657218 | G25: 45.443912 | H25: 0.133 | I25: 0 | J25: 13.515523 | K25: — | L25: 17.145955 | M25: -0.62270072 | N25: — | O25: — | P25: — | Q25: — | R25: — | S25: —
A26: 21 | B26: DLR | C26: Digital Realty Trust | D26: REIT - Office | E26: 173 | F26: 0.007982254 | G26: 65.33582 | H26: 0.299 | I26: 0.56994 | J26: 83.98058 | K26: 3768.482 | L26: 3.8116993 | M26: -0.94165989 | N26: 17.031468 | O26: — | P26: — | Q26: — | R26: — | S26: —
A27: 22 | B27: EQR | C27: Equity Residential | D27: REIT - Residential | E27: 63.66 | F27: -0.012717128 | G27: 24.609972 | H27: 0.021 | I27: 0.62336 | J27: 28.675674 | K27: 1423.1534 | L27: 4.11841 | M27: -0.8326528 | N27: 16.770821 | O27: — | P27: — | Q27: — | R27: — | S27: —
A28: 23 | B28: KEY | C28: KeyCorp | D28: Banks - Regional | E28: 19.92 | F28: 0.13568985 | G28: 21.257202 | H28: 0.101 | I28: 0 | J28: 11.581395 | K28: — | L28: 8.859944 | M28: -0.58320271 | N28: — | O28: — | P28: — | Q28: — | R28: — | S28: —
A29: 24 | B29: MKTX | C29: MarketAxess Holdings | D29: Capital Markets | E29: 164.53 | F29: -0.048574567 | G29: 5.7909944 | H29: -0.005 | I29: 0.61662996 | J29: 19.44799 | K29: -457.79002 | L29: 1.5571058 | M29: -0.73111599 | N29: -12.649893 | O29: — | P29: — | Q29: — | R29: — | S29: —
A30: 25 | B30: ARE | C30: Alexandria Real Estate | D30: REIT - Office | E30: 40.63 | F30: -0.47089463 | G30: 6.9922314 | H30: -0.119 | I30: 0.68198997 | J30: -50.160496 | K30: 1344.974 | L30: 2.0695483 | M30: -0.70402177 | N30: 5.1987855 | O30: — | P30: — | Q30: — | R30: — | S30: —
A31: 26 | B31: BIIB | C31: Biogen | D31: Drug Manufacturers - General | E31: 233.48 | F31: 0.59677196 | G31: 34.497602 | H31: 0.034 | I31: 0.78322 | J31: 41.47069 | K31: 1266.9875 | L31: 11.541485 | M31: -0.66544094 | N31: 27.228053 | O31: — | P31: — | Q31: — | R31: — | S31: —
A32: 27 | B32: MA | C32: Mastercard | D32: Credit Services | E32: 616.4 | F32: 0.07756591 | G32: 539.97253 | H32: 0.141 | I32: 1 | J32: 33.90539 | K32: 16961.25 | L32: 9.1340944 | M32: -0.98308415 | N32: 31.59777 | O32: SOLD | P32: — | Q32: Sold | R32: 90 | S32: Held since 2011 → Q1-26: ABEL FULLY EXITED with V. Combs-era payments exposure ended entirely
A33: 28 | B33: RF | C33: Regions Financial | D33: Banks - Regional | E33: 27.2 | F33: 0.11658454 | G33: 23.172483 | H33: 0.052 | I33: 0 | J33: 11.102041 | K33: — | L33: 10.270064 | M33: -0.55679917 | N33: — | O33: — | P33: — | Q33: — | R33: — | S33: —
A34: 29 | B34: MSCI | C34: MSCI | D34: Financial Data & Stock Exchanges | E34: 563.49 | F34: 0.042804837 | G34: 40.965722 | H34: 0.122 | I34: 0.82975 | J34: 30.791803 | K34: 1194.7059 | L34: — | M34: — | N34: 34.289378 | O34: — | P34: — | Q34: — | R34: — | S34: —
A35: 30 | B35: AVGO | C35: Broadcom | D35: Semiconductors | E35: 334.59 | F35: -0.023551047 | G35: 1597.2088 | H35: 0.855 | I35: 0.75515 | J35: 42.7318 | K35: 30596.499 | L35: 331.55864 | M35: -0.79241371 | N35: 52.202338 | O35: — | P35: — | Q35: — | R35: — | S35: —
A36: 31 | B36: PNC | C36: PNC Financial Services Gr | D36: Banks - Regional | E36: 216.21 | F36: 0.18855476 | G36: 86.255616 | H36: 0.109 | I36: 0 | J36: 11.574411 | K36: — | L36: 41.313085 | M36: -0.5210389 | N36: — | O36: — | P36: — | Q36: — | R36: — | S36: —
A37: 32 | B37: SBAC | C37: SBA Communications | D37: REIT - Specialty | E37: 183.09 | F37: -0.07375932 | G37: 19.423672 | H37: 0.023 | I37: 0.742 | J37: 19.750807 | K37: 752.05638 | L37: — | M37: — | N37: 25.827415 | O37: — | P37: — | Q37: — | R37: — | S37: —
A38: 33 | B38: TXN | C38: Texas Instruments | D38: Semiconductors | E38: 276.15 | F38: 0.5270405 | G38: 252.19334 | H38: 0.228 | I38: 0.58325 | J38: 42.031963 | K38: 3545.25 | L38: 41.247468 | M38: -0.83644505 | N38: 71.13556 | O38: — | P38: — | Q38: — | R38: — | S38: —
A39: 34 | B39: BXP | C39: Boston Properties | D39: REIT - Office | E39: 57.94 | F39: -0.19494236 | G39: 10.480038 | H39: 0.037 | I39: 0.56452 | J39: 31.150537 | K39: 880.63686 | L39: 1.3389336 | M39: -0.87223962 | N39: 10.50466 | O39: — | P39: — | Q39: — | R39: — | S39: —
A40: 35 | B40: SPGI | C40: S&P Global | D40: Financial Data & Stock Exchanges | E40: 427.83 | F40: -0.06526321 | G40: 126.12428 | H40: 0.104 | I40: 0.70903 | J40: 26.135 | K40: 5448.2499 | L40: 23.841224 | M40: -0.81097038 | N40: 23.149504 | O40: — | P40: — | Q40: — | R40: — | S40: —
...

Sheet Все компании
A1: № | B1: Company | D1: Ticker | E1: Share price | F1: 1 year change | G1: Market Cap | H1: IV | I1: Discount | J1: Growth annual | K1: Margin (gross) | L1: P/E | M1: Beta | N1: Tangible book value/share | O1: USD/RUB | P1: HKD/USD
E2: $ | F2: % | G2: mkn $ | H2: mln $ | J2: % | K2: % | O2: 77 | P2: 0.13
A3: =A2+1 | B3: =HYPERLINK("https://finance.yahoo.com/quote/"&D3, C3) | C3: Severstal' PAO | D3: SVST | E3: =IFERROR(__xludf.DUMMYFUNCTION("iferror(googlefinance(D3,""price""),"""")"),"") | F3: =IFERROR(__xludf.DUMMYFUNCTION("IFERROR(GOOGLEFINANCE(D3,""price"") / index(GOOGLEFINANCE(D3,""price"", datevalue(today()-365) ) , 2,2) - 1,"""")"),"") | G3: =IFERROR(__xludf.DUMMYFUNCTION("iferror(googlefinance(D3,""marketcap""),"""")/10^6"),0) | H3: =IFERROR(__xludf.DUMMYFUNCTION("IMPORTRANGE(""https://docs.google.com/spreadsheets/d/1dlfFsw9YFF_dEa-0WVRTnvUf7PBFwRrC6Y6BImZdJ_g/edit#gid=412432278"",""Summary!C30"")"),985803.888993602) | I3: =(H3-G3)/G3 | J3: =IFERROR(__xludf.DUMMYFUNCTION("IMPORTRANGE(""https://docs.google.com/spreadsheets/d/1dlfFsw9YFF_dEa-0WVRTnvUf7PBFwRrC6Y6BImZdJ_g/edit#gid=412432278"",""Summary!H2"")"),-0.157778595071717) | K3: =IFERROR(__xludf.DUMMYFUNCTION("IMPORTRANGE(""https://docs.google.com/spreadsheets/d/1dlfFsw9YFF_dEa-0WVRTnvUf7PBFwRrC6Y6BImZdJ_g/edit#gid=412432278"",""Summary!B16"")"),0.280931586608442) | L3: =IFERROR(__xludf.DUMMYFUNCTION("IFERROR(googlefinance(D3,""pe""),"""")"),"") | M3: =IFERROR(__xludf.DUMMYFUNCTION("IFERROR(googlefinance(D3,""beta""),"""")"),"")
A4: =A3+1 | B4: =HYPERLINK("https://finance.yahoo.com/quote/"&D4, C4) | C4: Sberbank Rossii PAO | D4: SBRCY | E4: =IFERROR(__xludf.DUMMYFUNCTION("iferror(googlefinance(D4,""price""),"""")"),"") | F4: =IFERROR(__xludf.DUMMYFUNCTION("IFERROR(GOOGLEFINANCE(D4,""price"") / index(GOOGLEFINANCE(D4,""price"", datevalue(today()-365) ) , 2,2) - 1,"""")"),"") | G4: =IFERROR(__xludf.DUMMYFUNCTION("iferror(googlefinance(D4,""marketcap""),"""")/10^6"),0) | H4: =IFERROR(__xludf.DUMMYFUNCTION("IMPORTRANGE(""https://docs.google.com/spreadsheets/d/1qkyVDQA4KrhGN7P_pvU-cCYRhkeObohXrHMSpHSzFaY/edit#gid=1866964818"",""Summary!C34"")"),9333100.82858735) | I4: =(H4-G4)/G4 | J4: =IFERROR(__xludf.DUMMYFUNCTION("IMPORTRANGE(""https://docs.google.com/spreadsheets/d/1qkyVDQA4KrhGN7P_pvU-cCYRhkeObohXrHMSpHSzFaY/edit#gid=1866964818"",""Summary!I2"")"),0.0894187779433681) | K4: =IFERROR(__xludf.DUMMYFUNCTION("IMPORTRANGE(""https://docs.google.com/spreadsheets/d/1qkyVDQA4KrhGN7P_pvU-cCYRhkeObohXrHMSpHSzFaY/edit#gid=1866964818"",""Summary!H20"")"),0.347013223894208) | L4: =IFERROR(__xludf.DUMMYFUNCTION("IFERROR(googlefinance(D4,""pe""),"""")"),"") | M4: =IFERROR(__xludf.DUMMYFUNCTION("IFERROR(googlefinance(D4,""beta""),"""")"),"")
A5: =A4+1 | B5: =HYPERLINK("https://finance.yahoo.com/quote/"&D5, C5) | C5: DouYu International Holdings Ltd | D5: DOYU | E5: =IFERROR(__xludf.DUMMYFUNCTION("iferror(googlefinance(D5,""price""),"""")"),5.28) | F5: =IFERROR(__xludf.DUMMYFUNCTION("IFERROR(GOOGLEFINANCE(D5,""price"") / index(GOOGLEFINANCE(D5,""price"", datevalue(today()-365) ) , 2,2) - 1,"""")"),-0.218934911242603) | G5: =IFERROR(__xludf.DUMMYFUNCTION("iferror(googlefinance(D5,""marketcap""),"""")/10^6"),163.952824) | H5: =IFERROR(__xludf.DUMMYFUNCTION("IMPORTRANGE(""https://docs.google.com/spreadsheets/d/1LupNll8EBZR0CxUoQzkZLRitp2lxm5UXiwXAxqniEg4/edit#gid=1537202402"",""DOYU!E29"")"),58.701638056861) | I5: =(H5-G5)/G5 | J5: =IFERROR(__xludf.DUMMYFUNCTION("IMPORTRANGE(""https://docs.google.com/spreadsheets/d/1LupNll8EBZR0CxUoQzkZLRitp2lxm5UXiwXAxqniEg4/edit#gid=1537202402"",""DOYU!I6"")"),5530) | K5: =IFERROR(__xludf.DUMMYFUNCTION("IMPORTRANGE(""https://docs.google.com/spreadsheets/d/1LupNll8EBZR0CxUoQzkZLRitp2lxm5UXiwXAxqniEg4/edit#gid=1537202402"",""DOYU!F23"")"),0.16248307467972) | L5: =IFERROR(__xludf.DUMMYFUNCTION("IFERROR(googlefinance(D5,""pe""),"""")"),"") | M5: =IFERROR(__xludf.DUMMYFUNCTION("IFERROR(googlefinance(D5,""beta""),"""")"),"")
A6: =A5+1 | B6: =HYPERLINK("https://finance.yahoo.com/quote/"&D6, C6) | C6: TCS Group Holding PLC | D6: TCSG | E6: =IFERROR(__xludf.DUMMYFUNCTION("iferror(googlefinance(D6,""price""),"""")"),"") | F6: =IFERROR(__xludf.DUMMYFUNCTION("IFERROR(GOOGLEFINANCE(D6,""price"") / index(GOOGLEFINANCE(D6,""price"", datevalue(today()-365) ) , 2,2) - 1,"""")"),"") | G6: =IFERROR(__xludf.DUMMYFUNCTION("iferror(googlefinance(D6,""marketcap""),"""")/10^6"),0) | H6: =IFERROR(__xludf.DUMMYFUNCTION("importrange(""https://docs.google.com/spreadsheets/d/1dcdnXtSf0zvBGYPG5ZVxziOJBBQiAwWkEZT-UAXL40I/edit#gid=1344089490"",""Summary!C36"")/#REF!*1000"),"#REF!") | I6: 0 | J6: =IFERROR(__xludf.DUMMYFUNCTION("importrange(""https://docs.google.com/spreadsheets/d/1dcdnXtSf0zvBGYPG5ZVxziOJBBQiAwWkEZT-UAXL40I/edit#gid=1344089490"",""Summary!J2"")"),0.78) | K6: =IFERROR(__xludf.DUMMYFUNCTION("importrange(""https://docs.google.com/spreadsheets/d/1dcdnXtSf0zvBGYPG5ZVxziOJBBQiAwWkEZT-UAXL40I/edit#gid=1344089490"",""Summary!I22"")"),0.351235955056179) | L6: =IFERROR(__xludf.DUMMYFUNCTION("IFERROR(googlefinance(D6,""pe""),"""")"),"") | M6: =IFERROR(__xludf.DUMMYFUNCTION("IFERROR(googlefinance(D6,""beta""),"""")"),"")
A7: =A6+1 | B7: =HYPERLINK("https://finance.yahoo.com/quote/"&D7, C7) | C7: Boeing Co | D7: BA | E7: =IFERROR(__xludf.DUMMYFUNCTION("iferror(googlefinance(D7,""price""),"""")"),227.53) | F7: =IFERROR(__xludf.DUMMYFUNCTION("IFERROR(GOOGLEFINANCE(D7,""price"") / index(GOOGLEFINANCE(D7,""price"", datevalue(today()-365) ) , 2,2) - 1,"""")"),0.337939550746795) | G7: =IFERROR(__xludf.DUMMYFUNCTION("iferror(googlefinance(D7,""marketcap""),"""")/10^6"),178690.024704) | H7: =IFERROR(__xludf.DUMMYFUNCTION("importrange(""https://docs.google.com/spreadsheets/d/1NdaSGlewe3S15DWFefRKHC-Z0tqbjFNPLDNlxW-5Kck/edit#gid=314785295"",""Financials!B41"")*1000"),63766.7712618821) | I7: =(H7-G7)/G7 | J7: =IFERROR(__xludf.DUMMYFUNCTION("importrange(""https://docs.google.com/spreadsheets/d/1NdaSGlewe3S15DWFefRKHC-Z0tqbjFNPLDNlxW-5Kck/edit#gid=314785295"",""Financials!F2"")"),-0.368018065699869) | K7: =IFERROR(__xludf.DUMMYFUNCTION("importrange(""https://docs.google.com/spreadsheets/d/1NdaSGlewe3S15DWFefRKHC-Z0tqbjFNPLDNlxW-5Kck/edit#gid=314785295"",""Financials!D19"")"),-0.0563899279772207) | L7: =IFERROR(__xludf.DUMMYFUNCTION("IFERROR(googlefinance(D7,""pe""),"""")"),"") | M7: =IFERROR(__xludf.DUMMYFUNCTION("IFERROR(googlefinance(D7,""beta""),"""")"),"")
A8: 1 | B8: =HYPERLINK("https://finance.yahoo.com/quote/"&D8, C8) | C8: GameStop Corp. | D8: GME | E8: =IFERROR(__xludf.DUMMYFUNCTION("iferror(googlefinance(D8,""price""),"""")"),24.03) | F8: =IFERROR(__xludf.DUMMYFUNCTION("IFERROR(GOOGLEFINANCE(D8,""price"") / index(GOOGLEFINANCE(D8,""price"", datevalue(today()-365) ) , 2,2) - 1,"""")"),-0.0151639344262294) | G8: =IFERROR(__xludf.DUMMYFUNCTION("iferror(googlefinance(D8,""marketcap""),"""")/10^6"),10765.668592) | H8: =IFERROR(__xludf.DUMMYFUNCTION("IMPORTRANGE(""https://docs.google.com/spreadsheets/d/1L4yfv89QVUE9L_HHdbGE4xVtgtA9FIdzCOWtDZY6v_8/edit#gid=469363836"",""Summary!B34"")"),4338.4200830816) | I8: =(H8-G8)/G8 | J8: =IFERROR(__xludf.DUMMYFUNCTION("IMPORTRANGE(""https://docs.google.com/spreadsheets/d/1L4yfv89QVUE9L_HHdbGE4xVtgtA9FIdzCOWtDZY6v_8/edit#gid=469363836"",""Summary!I3"")"),-0.247560964024813) | K8: =IFERROR(__xludf.DUMMYFUNCTION("IMPORTRANGE(""https://docs.google.com/spreadsheets/d/1L4yfv89QVUE9L_HHdbGE4xVtgtA9FIdzCOWtDZY6v_8/edit#gid=469363836"",""Summary!H11"")"),0.377315136288459) | L8: =IFERROR(__xludf.DUMMYFUNCTION("IFERROR(googlefinance(D8,""pe""),"""")"),"") | M8: =IFERROR(__xludf.DUMMYFUNCTION("IFERROR(googlefinance(D8,""beta""),"""")"),"")
A9: =A8+1 | B9: =HYPERLINK("https://finance.yahoo.com/quote/"&D9, C9) | C9: Baidu Inc | D9: BIDU | E9: =IFERROR(__xludf.DUMMYFUNCTION("iferror(googlefinance(D9,""price""),"""")"),124.44) | F9: =IFERROR(__xludf.DUMMYFUNCTION("IFERROR(GOOGLEFINANCE(D9,""price"") / index(GOOGLEFINANCE(D9,""price"", datevalue(today()-365) ) , 2,2) - 1,"""")"),0.475806451612903) | G9: =IFERROR(__xludf.DUMMYFUNCTION("iferror(googlefinance(D9,""marketcap""),"""")/10^6"),42778.851635) | H9: =IFERROR(__xludf.DUMMYFUNCTION("IMPORTRANGE(""https://docs.google.com/spreadsheets/d/1IVS0z4Rl2pa89mr25nlgvj339ilU2tVdVu3j7nFXQIc/edit#gid=300601680"",""Summary!B87"")*1000"),68732.0998158358) | I9: =(H9-G9)/G9 | J9: =IFERROR(__xludf.DUMMYFUNCTION("IMPORTRANGE(""https://docs.google.com/spreadsheets/d/1IVS0z4Rl2pa89mr25nlgvj339ilU2tVdVu3j7nFXQIc/edit#gid=300601680"",""Summary!N2"")"),-0.028912676056338) | K9: =IFERROR(__xludf.DUMMYFUNCTION("IMPORTRANGE(""https://docs.google.com/spreadsheets/d/1IVS0z4Rl2pa89mr25nlgvj339ilU2tVdVu3j7nFXQIc/edit#gid=300601680"",""Summary!G38"")"),0.239090343630986) | L9: =IFERROR(__xludf.DUMMYFUNCTION("IFERROR(googlefinance(D9,""pe""),"""")"),"") | M9: =IFERROR(__xludf.DUMMYFUNCTION("IFERROR(googlefinance(D9,""beta""),"""")"),"")
A10: =A9+1 | B10: =HYPERLINK("https://finance.yahoo.com/quote/"&#REF!, C10) | C10: Southwest Airlines Co | E10: =IFERROR(__xludf.DUMMYFUNCTION("iferror(googlefinance(#REF!,""price""),"""")"),"") | F10: =IFERROR(__xludf.DUMMYFUNCTION("IFERROR(GOOGLEFINANCE(#REF!,""price"") / index(GOOGLEFINANCE(#REF!,""price"", datevalue(today()-365) ) , 2,2) - 1,"""")"),"") | G10: =IFERROR(__xludf.DUMMYFUNCTION("iferror(googlefinance(#REF!,""marketcap""),"""")/10^6"),0) | H10: =IFERROR(__xludf.DUMMYFUNCTION("importrange(""https://docs.google.com/spreadsheets/d/134U-14NIeFgI3O-C1JHtY0ItSiJlwkxRAneHpKC9G-c/edit#gid=893603675"",""Financials!B49"")*1000"),31298.0232402297) | I10: =(H10-G10)/G10 | K10: =IFERROR(__xludf.DUMMYFUNCTION("importrange(""https://docs.google.com/spreadsheets/d/134U-14NIeFgI3O-C1JHtY0ItSiJlwkxRAneHpKC9G-c/edit#gid=893603675"",""Financials!H16"")"),0.0984871957621025) | L10: =IFERROR(__xludf.DUMMYFUNCTION("IFERROR(googlefinance(#REF!,""pe""),"""")"),"") | M10: =IFERROR(__xludf.DUMMYFUNCTION("IFERROR(googlefinance(#REF!,""beta""),"""")"),"")
A11: =A10+1 | B11: =HYPERLINK("https://finance.yahoo.com/quote/"&D11, C11) | C11: American Airlines Group Inc | D11: AAL | E11: =IFERROR(__xludf.DUMMYFUNCTION("iferror(googlefinance(D11,""price""),"""")"),13.07) | F11: =IFERROR(__xludf.DUMMYFUNCTION("IFERROR(GOOGLEFINANCE(D11,""price"") / index(GOOGLEFINANCE(D11,""price"", datevalue(today()-365) ) , 2,2) - 1,"""")"),-0.0576784426820474) | G11: =IFERROR(__xludf.DUMMYFUNCTION("iferror(googlefinance(D11,""marketcap""),"""")/10^6"),8630.179613) | H11: =IFERROR(__xludf.DUMMYFUNCTION("importrange(""https://docs.google.com/spreadsheets/d/1Y-0VcPnHxxHb4ZZr1UWvNQuaZIkoxtvWgysgmaSL9Gs/edit#gid=1635501517"",""Financials!B48"")*1000"),14832.1796340825) | I11: =(H11-G11)/G11 | J11: =IFERROR(__xludf.DUMMYFUNCTION("importrange(""https://docs.google.com/spreadsheets/d/1Y-0VcPnHxxHb4ZZr1UWvNQuaZIkoxtvWgysgmaSL9Gs/edit#gid=1635501517"",""Financials!Q3"")"),0.0116950434413679) | K11: =IFERROR(__xludf.DUMMYFUNCTION("importrange(""https://docs.google.com/spreadsheets/d/1Y-0VcPnHxxHb4ZZr1UWvNQuaZIkoxtvWgysgmaSL9Gs/edit#gid=1635501517"",""Financials!M16"")"),0) | L11: =IFERROR(__xludf.DUMMYFUNCTION("IFERROR(googlefinance(D11,""pe""),"""")"),"") | M11: =IFERROR(__xludf.DUMMYFUNCTION("IFERROR(googlefinance(D11,""beta""),"""")"),"") | N11: =IFERROR(__xludf.DUMMYFUNCTION("IMPORTRANGE(""https://docs.google.com/spreadsheets/d/1zPx-sYL2WZELC72hI-Xc5oMEa-YaHSyQySKfbmi4y7s/edit#gid=303626986"",""Summary!I13"")"),32.23)
A12: =A11+1 | B12: =HYPERLINK("https://finance.yahoo.com/quote/"&D12, C12) | C12: Synchrony | D12: SYF | E12: =IFERROR(__xludf.DUMMYFUNCTION("iferror(googlefinance(D12,""price""),"""")"),69.11) | F12: =IFERROR(__xludf.DUMMYFUNCTION("IFERROR(GOOGLEFINANCE(D12,""price"") / index(GOOGLEFINANCE(D12,""price"", datevalue(today()-365) ) , 2,2) - 1,"""")"),0.191140985866942) | G12: =IFERROR(__xludf.DUMMYFUNCTION("iferror(googlefinance(D12,""marketcap""),"""")/10^6"),24022.373594) | H12: =IFERROR(__xludf.DUMMYFUNCTION("IMPORTRANGE(""https://docs.google.com/spreadsheets/d/1iemsJA0zDOHQP6QC15q0vMx_VbJPUq1by9erqpBNeOY/edit#gid=1736956277"",""SYF!C28"")"),47018.17007173) | I12: =(H12-G12)/G12 | J12: =IFERROR(__xludf.DUMMYFUNCTION("IMPORTRANGE(""https://docs.google.com/spreadsheets/d/1iemsJA0zDOHQP6QC15q0vMx_VbJPUq1by9erqpBNeOY/edit#gid=1736956277"",""SYF!M2"")"),20759) | K12: =IFERROR(__xludf.DUMMYFUNCTION("IMPORTRANGE(""https://docs.google.com/spreadsheets/d/1iemsJA0zDOHQP6QC15q0vMx_VbJPUq1by9erqpBNeOY/edit#gid=1736956277"",""SYF!I17"")"),0.111844152610941) | L12: =IFERROR(__xludf.DUMMYFUNCTION("IFERROR(googlefinance(D12,""pe""),"""")"),"") | M12: =IFERROR(__xludf.DUMMYFUNCTION("IFERROR(googlefinance(D12,""beta""),"""")"),"")
A13: =A12+1 | B13: =HYPERLINK("https://finance.yahoo.com/quote/"&D13, C13) | C13: JPMorgan Chase & Co. | D13: JPM | E13: =IFERROR(__xludf.DUMMYFUNCTION("iferror(googlefinance(D13,""price""),"""")"),300.3) | F13: =IFERROR(__xludf.DUMMYFUNCTION("IFERROR(GOOGLEFINANCE(D13,""price"") / index(GOOGLEFINANCE(D13,""price"", datevalue(today()-365) ) , 2,2) - 1,"""")"),0.15225232138746) | G13: =IFERROR(__xludf.DUMMYFUNCTION("iferror(googlefinance(D13,""marketcap""),"""")/10^6"),809918.676677) | H13: =IFERROR(__xludf.DUMMYFUNCTION("IMPORTRANGE(""https://docs.google.com/spreadsheets/d/18ffdmQve-35mEbb2ekY2flpF2A2bw2ki4JoC3jzdg1I/edit#gid=650781654"",""JPM!B1"")*1000"),426806.632058656) | I13: =(H13-G13)/G13 | J13: =IFERROR(__xludf.DUMMYFUNCTION("IMPORTRANGE(""https://docs.google.com/spreadsheets/d/18ffdmQve-35mEbb2ekY2flpF2A2bw2ki4JoC3jzdg1I/edit#gid=650781654"",""JPM!I53"")"),0.0265768375898362) | K13: =IFERROR(__xludf.DUMMYFUNCTION("IMPORTRANGE(""https://docs.google.com/spreadsheets/d/18ffdmQve-35mEbb2ekY2flpF2A2bw2ki4JoC3jzdg1I/edit#gid=650781654"",""JPM!H65"")"),0.262535804549283) | L13: =IFERROR(__xludf.DUMMYFUNCTION("G13/IMPORTRANGE(""https://docs.google.com/spreadsheets/d/18ffdmQve-35mEbb2ekY2flpF2A2bw2ki4JoC3jzdg1I/edit#gid=650781654"",""JPM!H55"")"),33.3423357077518) | M13: =IFERROR(__xludf.DUMMYFUNCTION("IFERROR(googlefinance(D13,""beta""),"""")"),"")
A14: =A13+1 | B14: =HYPERLINK("https://finance.yahoo.com/quote/"&D14, C14) | C14: United Airlines Holdings Inc | D14: UAL | E14: =IFERROR(__xludf.DUMMYFUNCTION("iferror(googlefinance(D14,""price""),"""")"),106.3) | F14: =IFERROR(__xludf.DUMMYFUNCTION("IFERROR(GOOGLEFINANCE(D14,""price"") / index(GOOGLEFINANCE(D14,""price"", datevalue(today()-365) ) , 2,2) - 1,"""")"),0.159594196574669) | G14: =IFERROR(__xludf.DUMMYFUNCTION("iferror(googlefinance(D14,""marketcap""),"""")/10^6"),34380.641877) | H14: =IFERROR(__xludf.DUMMYFUNCTION("importrange(""https://docs.google.com/spreadsheets/d/1E88W75oZAuEU3j_FKIjWcy8x6xr33WZ1jtcDeEarqCM/edit#gid=1816187640"",""Summary!B27"")"),21653.5369773099) | I14: =(H14-G14)/G14 | J14: =IFERROR(__xludf.DUMMYFUNCTION("importrange(""https://docs.google.com/spreadsheets/d/1E88W75oZAuEU3j_FKIjWcy8x6xr33WZ1jtcDeEarqCM/edit#gid=1816187640"",""Summary!F2"")"),-0.352566585956416) | K14: =IFERROR(__xludf.DUMMYFUNCTION("importrange(""https://docs.google.com/spreadsheets/d/1E88W75oZAuEU3j_FKIjWcy8x6xr33WZ1jtcDeEarqCM/edit#gid=1816187640"",""Summary!D14"")"),0.0994243972352574) | L14: =IFERROR(__xludf.DUMMYFUNCTION("IFERROR(googlefinance(D14,""pe""),"""")"),"") | M14: =IFERROR(__xludf.DUMMYFUNCTION("IFERROR(googlefinance(D14,""beta""),"""")"),"")
A15: =A14+1 | B15: =HYPERLINK("https://finance.yahoo.com/quote/"&D15, C15) | C15: U.S. Bancorp | D15: USB | E15: =IFERROR(__xludf.DUMMYFUNCTION("iferror(googlefinance(D15,""price""),"""")"),54.66) | F15: =IFERROR(__xludf.DUMMYFUNCTION("IFERROR(GOOGLEFINANCE(D15,""price"") / index(GOOGLEFINANCE(D15,""price"", datevalue(today()-365) ) , 2,2) - 1,"""")"),0.182093425605536) | G15: =IFERROR(__xludf.DUMMYFUNCTION("iferror(googlefinance(D15,""marketcap""),"""")/10^6"),84924.968462) | H15: =IFERROR(__xludf.DUMMYFUNCTION("IMPORTRANGE(""https://docs.google.com/spreadsheets/d/1BkE_9jEXhHz4aashYd9x7c-jGM6MGTH38F1LR9rqUwQ/edit#gid=467477759"",""Summary!C29"")"),120236.19642455) | I15: =(H15-G15)/G15 | J15: =IFERROR(__xludf.DUMMYFUNCTION("IMPORTRANGE(""https://docs.google.com/spreadsheets/d/1BkE_9jEXhHz4aashYd9x7c-jGM6MGTH38F1LR9rqUwQ/edit#gid=467477759"",""Summary!M2"")"),0.225660439470002) | K15: =IFERROR(__xludf.DUMMYFUNCTION("IMPORTRANGE(""https://docs.google.com/spreadsheets/d/1BkE_9jEXhHz4aashYd9x7c-jGM6MGTH38F1LR9rqUwQ/edit#gid=467477759"",""Summary!I19"")"),0.212604501607717) | L15: =IFERROR(__xludf.DUMMYFUNCTION("IFERROR(googlefinance(D15,""pe""),"""")"),"") | M15: =IFERROR(__xludf.DUMMYFUNCTION("IFERROR(googlefinance(D15,""beta""),"""")"),"") | N15: =IFERROR(__xludf.DUMMYFUNCTION("IMPORTRANGE(""https://docs.google.com/spreadsheets/d/18ffdmQve-35mEbb2ekY2flpF2A2bw2ki4JoC3jzdg1I/edit#gid=650781654"",""JPM!H72"")"),61.76)
A16: =A15+1 | B16: =HYPERLINK("https://finance.yahoo.com/quote/"&D16, C16) | C16: Bank of America Corp | D16: BAC | E16: =IFERROR(__xludf.DUMMYFUNCTION("iferror(googlefinance(D16,""price""),"""")"),49.83) | F16: =IFERROR(__xludf.DUMMYFUNCTION("IFERROR(GOOGLEFINANCE(D16,""price"") / index(GOOGLEFINANCE(D16,""price"", datevalue(today()-365) ) , 2,2) - 1,"""")"),0.0937225636523264) | G16: =IFERROR(__xludf.DUMMYFUNCTION("iferror(googlefinance(D16,""marketcap""),"""")/10^6"),357614.0772) | H16: =IFERROR(__xludf.DUMMYFUNCTION("IMPORTRANGE(""https://docs.google.com/spreadsheets/d/1ajry6MlMHVl1AsbljgX5BXpRLc8MVU1N9Z23HIyADoU/edit#gid=1672282254"",""Summary!B73"")"),258602.069066145) | I16: =(H16-G16)/G16 | J16: =IFERROR(__xludf.DUMMYFUNCTION("IMPORTRANGE(""https://docs.google.com/spreadsheets/d/1ajry6MlMHVl1AsbljgX5BXpRLc8MVU1N9Z23HIyADoU/edit#gid=1672282254"",""Summary!K48"")"),-0.01889645632832) | K16: =IFERROR(__xludf.DUMMYFUNCTION("IMPORTRANGE(""https://docs.google.com/spreadsheets/d/1ajry6MlMHVl1AsbljgX5BXpRLc8MVU1N9Z23HIyADoU/edit#gid=1672282254"",""Summary!I64"")"),0.21958338706085) | L16: =IFERROR(__xludf.DUMMYFUNCTION("IFERROR(googlefinance(D16,""pe""),"""")"),"") | M16: =IFERROR(__xludf.DUMMYFUNCTION("IFERROR(googlefinance(D16,""beta""),"""")"),"") | N16: =IFERROR(__xludf.DUMMYFUNCTION("IMPORTRANGE(""https://docs.google.com/spreadsheets/d/1BkE_9jEXhHz4aashYd9x7c-jGM6MGTH38F1LR9rqUwQ/edit#gid=467477759"",""Summary!I21"")"),30.24)
A17: =A16+1 | B17: =HYPERLINK("https://finance.yahoo.com/quote/"&D17, C17) | C17: Delta Air Lines, Inc. | D17: DAL | E17: =IFERROR(__xludf.DUMMYFUNCTION("iferror(googlefinance(D17,""price""),"""")"),65.7) | F17: =IFERROR(__xludf.DUMMYFUNCTION("IFERROR(GOOGLEFINANCE(D17,""price"") / index(GOOGLEFINANCE(D17,""price"", datevalue(today()-365) ) , 2,2) - 1,"""")"),0.124037639007698) | G17: =IFERROR(__xludf.DUMMYFUNCTION("iferror(googlefinance(D17,""marketcap""),"""")/10^6"),42910.684996) | H17: =IFERROR(__xludf.DUMMYFUNCTION("IMPORTRANGE(""https://docs.google.com/spreadsheets/d/1Z6RobysQCGMiI-pRQ6lMweET1m6J6B9TgwscNtCNb1g/edit#gid=428240719"",""Financials!B46"")*1000"),3385.90206884782) | I17: =(H17-G17)/G17 | J17: =IFERROR(__xludf.DUMMYFUNCTION("IMPORTRANGE(""https://docs.google.com/spreadsheets/d/1Z6RobysQCGMiI-pRQ6lMweET1m6J6B9TgwscNtCNb1g/edit#gid=428240719"",""Financials!I3"")"),-0.636330759248622) | K17: =IFERROR(__xludf.DUMMYFUNCTION("IMPORTRANGE(""https://docs.google.com/spreadsheets/d/1Z6RobysQCGMiI-pRQ6lMweET1m6J6B9TgwscNtCNb1g/edit#gid=428240719"",""Financials!H16"")"),-0.72939455981281) | L17: =IFERROR(__xludf.DUMMYFUNCTION("IFERROR(googlefinance(D17,""pe""),"""")"),"") | M17: =IFERROR(__xludf.DUMMYFUNCTION("IFERROR(googlefinance(D17,""beta""),"""")"),"") | N17: =IFERROR(__xludf.DUMMYFUNCTION("IMPORTRANGE(""https://docs.google.com/spreadsheets/d/1ajry6MlMHVl1AsbljgX5BXpRLc8MVU1N9Z23HIyADoU/edit#gid=1672282254"",""Summary!I59"")"),19.9)
